[2024-08-16T21:53:17.956+0000] {taskinstance.py:1157} INFO - Dependencies all met for dep_context=non-requeueable deps ti=<TaskInstance: postgres_to_bigquery_etl.process_olist_orders.load_olist_orders_to_gcs manual__2024-08-16T15:47:41.371680+00:00 [queued]>
[2024-08-16T21:53:17.973+0000] {taskinstance.py:1157} INFO - Dependencies all met for dep_context=requeueable deps ti=<TaskInstance: postgres_to_bigquery_etl.process_olist_orders.load_olist_orders_to_gcs manual__2024-08-16T15:47:41.371680+00:00 [queued]>
[2024-08-16T21:53:17.974+0000] {taskinstance.py:1359} INFO - Starting attempt 8 of 8
[2024-08-16T21:53:18.340+0000] {taskinstance.py:1380} INFO - Executing <Task(PostgresToGCSOperator): process_olist_orders.load_olist_orders_to_gcs> on 2024-08-16 15:47:41.371680+00:00
[2024-08-16T21:53:18.353+0000] {standard_task_runner.py:57} INFO - Started process 1221 to run task
[2024-08-16T21:53:18.360+0000] {standard_task_runner.py:84} INFO - Running: ['***', 'tasks', 'run', 'postgres_to_bigquery_etl', 'process_olist_orders.load_olist_orders_to_gcs', 'manual__2024-08-16T15:47:41.371680+00:00', '--job-id', '691', '--raw', '--subdir', 'DAGS_FOLDER/extract_from_pg.py', '--cfg-path', '/tmp/tmp2hx8yva9']
[2024-08-16T21:53:18.364+0000] {standard_task_runner.py:85} INFO - Job 691: Subtask process_olist_orders.load_olist_orders_to_gcs
[2024-08-16T21:53:18.937+0000] {task_command.py:415} INFO - Running <TaskInstance: postgres_to_bigquery_etl.process_olist_orders.load_olist_orders_to_gcs manual__2024-08-16T15:47:41.371680+00:00 [running]> on host c04129f4379c
[2024-08-16T21:53:19.232+0000] {warnings.py:109} WARNING - /home/***/.local/lib/python3.8/site-packages/***/utils/context.py:206: AirflowContextDeprecationWarning: Accessing 'execution_date' from the template is deprecated and will be removed in a future version. Please use 'data_interval_start' or 'logical_date' instead.
  warnings.warn(_create_deprecation_warning(key, self._deprecation_replacements[key]))

[2024-08-16T21:53:19.305+0000] {taskinstance.py:1660} INFO - Exporting env vars: AIRFLOW_CTX_DAG_OWNER='***' AIRFLOW_CTX_DAG_ID='postgres_to_bigquery_etl' AIRFLOW_CTX_TASK_ID='process_olist_orders.load_olist_orders_to_gcs' AIRFLOW_CTX_EXECUTION_DATE='2024-08-16T15:47:41.371680+00:00' AIRFLOW_CTX_TRY_NUMBER='8' AIRFLOW_CTX_DAG_RUN_ID='manual__2024-08-16T15:47:41.371680+00:00'
[2024-08-16T21:53:19.311+0000] {sql_to_gcs.py:161} INFO - Executing query
[2024-08-16T21:53:19.362+0000] {base.py:73} INFO - Using connection ID 'source_postgres_db' for task execution.
[2024-08-16T21:53:19.845+0000] {sql_to_gcs.py:180} INFO - Writing local data files
[2024-08-16T21:53:36.954+0000] {sql_to_gcs.py:186} INFO - Uploading chunk file #0 to GCS.
[2024-08-16T21:53:36.971+0000] {connection.py:232} WARNING - Connection schemes (type: google_cloud_platform) shall not contain '_' according to RFC3986.
[2024-08-16T21:53:36.977+0000] {base.py:73} INFO - Using connection ID 'google_cloud_default' for task execution.
[2024-08-16T21:53:37.164+0000] {connectionpool.py:823} WARNING - Retrying (Retry(total=2, connect=None, read=None, redirect=None, status=None)) after connection broken by 'NewConnectionError('<urllib3.connection.HTTPSConnection object at 0x731826750730>: Failed to establish a new connection: [Errno -3] Temporary failure in name resolution')': /token
[2024-08-16T21:53:37.172+0000] {connectionpool.py:823} WARNING - Retrying (Retry(total=1, connect=None, read=None, redirect=None, status=None)) after connection broken by 'NewConnectionError('<urllib3.connection.HTTPSConnection object at 0x7318267508b0>: Failed to establish a new connection: [Errno -3] Temporary failure in name resolution')': /token
[2024-08-16T21:53:37.178+0000] {connectionpool.py:823} WARNING - Retrying (Retry(total=0, connect=None, read=None, redirect=None, status=None)) after connection broken by 'NewConnectionError('<urllib3.connection.HTTPSConnection object at 0x731826750a30>: Failed to establish a new connection: [Errno -3] Temporary failure in name resolution')': /token
[2024-08-16T21:53:37.184+0000] {taskinstance.py:1935} ERROR - Task failed with exception
Traceback (most recent call last):
  File "/home/airflow/.local/lib/python3.8/site-packages/urllib3/connection.py", line 174, in _new_conn
    conn = connection.create_connection(
  File "/home/airflow/.local/lib/python3.8/site-packages/urllib3/util/connection.py", line 72, in create_connection
    for res in socket.getaddrinfo(host, port, family, socket.SOCK_STREAM):
  File "/usr/local/lib/python3.8/socket.py", line 918, in getaddrinfo
    for res in _socket.getaddrinfo(host, port, family, type, proto, flags):
socket.gaierror: [Errno -3] Temporary failure in name resolution

During handling of the above exception, another exception occurred:

Traceback (most recent call last):
  File "/home/airflow/.local/lib/python3.8/site-packages/urllib3/connectionpool.py", line 714, in urlopen
    httplib_response = self._make_request(
  File "/home/airflow/.local/lib/python3.8/site-packages/urllib3/connectionpool.py", line 403, in _make_request
    self._validate_conn(conn)
  File "/home/airflow/.local/lib/python3.8/site-packages/urllib3/connectionpool.py", line 1053, in _validate_conn
    conn.connect()
  File "/home/airflow/.local/lib/python3.8/site-packages/urllib3/connection.py", line 363, in connect
    self.sock = conn = self._new_conn()
  File "/home/airflow/.local/lib/python3.8/site-packages/urllib3/connection.py", line 186, in _new_conn
    raise NewConnectionError(
urllib3.exceptions.NewConnectionError: <urllib3.connection.HTTPSConnection object at 0x731826750be0>: Failed to establish a new connection: [Errno -3] Temporary failure in name resolution

During handling of the above exception, another exception occurred:

Traceback (most recent call last):
  File "/home/airflow/.local/lib/python3.8/site-packages/requests/adapters.py", line 486, in send
    resp = conn.urlopen(
  File "/home/airflow/.local/lib/python3.8/site-packages/urllib3/connectionpool.py", line 826, in urlopen
    return self.urlopen(
  File "/home/airflow/.local/lib/python3.8/site-packages/urllib3/connectionpool.py", line 826, in urlopen
    return self.urlopen(
  File "/home/airflow/.local/lib/python3.8/site-packages/urllib3/connectionpool.py", line 826, in urlopen
    return self.urlopen(
  File "/home/airflow/.local/lib/python3.8/site-packages/urllib3/connectionpool.py", line 798, in urlopen
    retries = retries.increment(
  File "/home/airflow/.local/lib/python3.8/site-packages/urllib3/util/retry.py", line 592, in increment
    raise MaxRetryError(_pool, url, error or ResponseError(cause))
urllib3.exceptions.MaxRetryError: HTTPSConnectionPool(host='oauth2.googleapis.com', port=443): Max retries exceeded with url: /token (Caused by NewConnectionError('<urllib3.connection.HTTPSConnection object at 0x731826750be0>: Failed to establish a new connection: [Errno -3] Temporary failure in name resolution'))

During handling of the above exception, another exception occurred:

Traceback (most recent call last):
  File "/home/airflow/.local/lib/python3.8/site-packages/google/auth/transport/requests.py", line 193, in __call__
    response = self.session.request(
  File "/home/airflow/.local/lib/python3.8/site-packages/requests/sessions.py", line 589, in request
    resp = self.send(prep, **send_kwargs)
  File "/home/airflow/.local/lib/python3.8/site-packages/requests/sessions.py", line 703, in send
    r = adapter.send(request, **kwargs)
  File "/home/airflow/.local/lib/python3.8/site-packages/requests/adapters.py", line 519, in send
    raise ConnectionError(e, request=request)
requests.exceptions.ConnectionError: HTTPSConnectionPool(host='oauth2.googleapis.com', port=443): Max retries exceeded with url: /token (Caused by NewConnectionError('<urllib3.connection.HTTPSConnection object at 0x731826750be0>: Failed to establish a new connection: [Errno -3] Temporary failure in name resolution'))

The above exception was the direct cause of the following exception:

Traceback (most recent call last):
  File "/home/airflow/.local/lib/python3.8/site-packages/airflow/providers/google/cloud/transfers/sql_to_gcs.py", line 187, in execute
    self._upload_to_gcs(file_to_upload)
  File "/home/airflow/.local/lib/python3.8/site-packages/airflow/providers/google/cloud/transfers/sql_to_gcs.py", line 494, in _upload_to_gcs
    hook.upload(
  File "/home/airflow/.local/lib/python3.8/site-packages/airflow/providers/google/cloud/hooks/gcs.py", line 558, in upload
    _call_with_retry(
  File "/home/airflow/.local/lib/python3.8/site-packages/airflow/providers/google/cloud/hooks/gcs.py", line 513, in _call_with_retry
    f()
  File "/home/airflow/.local/lib/python3.8/site-packages/google/cloud/storage/blob.py", line 2684, in upload_from_filename
    self.upload_from_file(
  File "/home/airflow/.local/lib/python3.8/site-packages/google/cloud/storage/blob.py", line 2540, in upload_from_file
    created_json = self._do_upload(
  File "/home/airflow/.local/lib/python3.8/site-packages/google/cloud/storage/blob.py", line 2371, in _do_upload
    response = self._do_resumable_upload(
  File "/home/airflow/.local/lib/python3.8/site-packages/google/cloud/storage/blob.py", line 2198, in _do_resumable_upload
    upload, transport = self._initiate_resumable_upload(
  File "/home/airflow/.local/lib/python3.8/site-packages/google/cloud/storage/blob.py", line 2079, in _initiate_resumable_upload
    upload.initiate(
  File "/home/airflow/.local/lib/python3.8/site-packages/google/resumable_media/requests/upload.py", line 420, in initiate
    return _request_helpers.wait_and_retry(
  File "/home/airflow/.local/lib/python3.8/site-packages/google/resumable_media/requests/_request_helpers.py", line 155, in wait_and_retry
    response = func()
  File "/home/airflow/.local/lib/python3.8/site-packages/google/resumable_media/requests/upload.py", line 412, in retriable_request
    result = transport.request(
  File "/home/airflow/.local/lib/python3.8/site-packages/google/auth/transport/requests.py", line 545, in request
    self.credentials.before_request(auth_request, method, url, request_headers)
  File "/home/airflow/.local/lib/python3.8/site-packages/google/auth/credentials.py", line 156, in before_request
    self.refresh(request)
  File "/home/airflow/.local/lib/python3.8/site-packages/google/oauth2/service_account.py", line 438, in refresh
    access_token, expiry, _ = _client.jwt_grant(
  File "/home/airflow/.local/lib/python3.8/site-packages/google/oauth2/_client.py", line 312, in jwt_grant
    response_data = _token_endpoint_request(
  File "/home/airflow/.local/lib/python3.8/site-packages/google/oauth2/_client.py", line 272, in _token_endpoint_request
    response_status_ok, response_data, retryable_error = _token_endpoint_request_no_throw(
  File "/home/airflow/.local/lib/python3.8/site-packages/google/oauth2/_client.py", line 219, in _token_endpoint_request_no_throw
    request_succeeded, response_data, retryable_error = _perform_request()
  File "/home/airflow/.local/lib/python3.8/site-packages/google/oauth2/_client.py", line 195, in _perform_request
    response = request(
  File "/home/airflow/.local/lib/python3.8/site-packages/google/auth/transport/requests.py", line 199, in __call__
    six.raise_from(new_exc, caught_exc)
  File "<string>", line 3, in raise_from
google.auth.exceptions.TransportError: HTTPSConnectionPool(host='oauth2.googleapis.com', port=443): Max retries exceeded with url: /token (Caused by NewConnectionError('<urllib3.connection.HTTPSConnection object at 0x731826750be0>: Failed to establish a new connection: [Errno -3] Temporary failure in name resolution'))
[2024-08-16T21:53:38.354+0000] {taskinstance.py:1398} INFO - Marking task as FAILED. dag_id=postgres_to_bigquery_etl, task_id=process_olist_orders.load_olist_orders_to_gcs, execution_date=20240816T154741, start_date=20240816T215317, end_date=20240816T215338
[2024-08-16T21:53:39.748+0000] {standard_task_runner.py:104} ERROR - Failed to execute job 691 for task process_olist_orders.load_olist_orders_to_gcs (HTTPSConnectionPool(host='oauth2.googleapis.com', port=443): Max retries exceeded with url: /token (Caused by NewConnectionError('<urllib3.connection.HTTPSConnection object at 0x731826750be0>: Failed to establish a new connection: [Errno -3] Temporary failure in name resolution')); 1221)
[2024-08-16T21:53:39.780+0000] {local_task_job_runner.py:228} INFO - Task exited with return code 1
[2024-08-16T21:53:39.825+0000] {taskinstance.py:2776} INFO - 0 downstream tasks scheduled from follow-on schedule check
