[2024-08-15T05:49:41.406+0000] {taskinstance.py:1157} INFO - Dependencies all met for dep_context=non-requeueable deps ti=<TaskInstance: postgres_to_bigquery_etl.create_bigquery_dataset manual__2024-08-15T04:06:26.658756+00:00 [queued]>
[2024-08-15T05:49:41.422+0000] {taskinstance.py:1157} INFO - Dependencies all met for dep_context=requeueable deps ti=<TaskInstance: postgres_to_bigquery_etl.create_bigquery_dataset manual__2024-08-15T04:06:26.658756+00:00 [queued]>
[2024-08-15T05:49:41.423+0000] {taskinstance.py:1359} INFO - Starting attempt 2 of 5
[2024-08-15T05:49:41.448+0000] {taskinstance.py:1380} INFO - Executing <Task(BigQueryCreateEmptyDatasetOperator): create_bigquery_dataset> on 2024-08-15 04:06:26.658756+00:00
[2024-08-15T05:49:41.462+0000] {standard_task_runner.py:57} INFO - Started process 35245 to run task
[2024-08-15T05:49:41.468+0000] {standard_task_runner.py:84} INFO - Running: ['***', 'tasks', 'run', 'postgres_to_bigquery_etl', 'create_bigquery_dataset', 'manual__2024-08-15T04:06:26.658756+00:00', '--job-id', '615', '--raw', '--subdir', 'DAGS_FOLDER/extract_from_pg.py', '--cfg-path', '/tmp/tmps5b0k54k']
[2024-08-15T05:49:41.474+0000] {standard_task_runner.py:85} INFO - Job 615: Subtask create_bigquery_dataset
[2024-08-15T05:49:41.566+0000] {task_command.py:415} INFO - Running <TaskInstance: postgres_to_bigquery_etl.create_bigquery_dataset manual__2024-08-15T04:06:26.658756+00:00 [running]> on host d81d956e7878
[2024-08-15T05:49:41.748+0000] {taskinstance.py:1660} INFO - Exporting env vars: AIRFLOW_CTX_DAG_OWNER='***' AIRFLOW_CTX_DAG_ID='postgres_to_bigquery_etl' AIRFLOW_CTX_TASK_ID='create_bigquery_dataset' AIRFLOW_CTX_EXECUTION_DATE='2024-08-15T04:06:26.658756+00:00' AIRFLOW_CTX_TRY_NUMBER='2' AIRFLOW_CTX_DAG_RUN_ID='manual__2024-08-15T04:06:26.658756+00:00'
[2024-08-15T05:49:41.770+0000] {connection.py:232} WARNING - Connection schemes (type: google_cloud_platform) shall not contain '_' according to RFC3986.
[2024-08-15T05:49:41.789+0000] {base.py:73} INFO - Using connection ID 'google_cloud_default' for task execution.
[2024-08-15T05:49:41.793+0000] {bigquery.py:470} INFO - datasetId was not specified in `dataset_reference`. Will use default value olist_ecommerce_data2.
[2024-08-15T05:49:41.794+0000] {bigquery.py:470} INFO - projectId was not specified in `dataset_reference`. Will use default value utility-range-425622-c7.
[2024-08-15T05:49:41.797+0000] {bigquery.py:481} INFO - Creating dataset: olist_ecommerce_data2 in project: utility-range-425622-c7 
[2024-08-15T05:49:44.929+0000] {bigquery.py:485} INFO - Dataset created successfully.
[2024-08-15T05:49:44.985+0000] {taskinstance.py:1398} INFO - Marking task as SUCCESS. dag_id=postgres_to_bigquery_etl, task_id=create_bigquery_dataset, execution_date=20240815T040626, start_date=20240815T054941, end_date=20240815T054944
[2024-08-15T05:49:45.058+0000] {local_task_job_runner.py:228} INFO - Task exited with return code 0
[2024-08-15T05:49:45.176+0000] {taskinstance.py:2776} INFO - 9 downstream tasks scheduled from follow-on schedule check
