[2024-08-14T20:51:28.060+0000] {taskinstance.py:1157} INFO - Dependencies all met for dep_context=non-requeueable deps ti=<TaskInstance: postgres_to_bigquery_etl.process_olist_customers.load_olist_customers_to_gcs manual__2024-08-14T20:43:10.489736+00:00 [queued]>
[2024-08-14T20:51:28.089+0000] {taskinstance.py:1157} INFO - Dependencies all met for dep_context=requeueable deps ti=<TaskInstance: postgres_to_bigquery_etl.process_olist_customers.load_olist_customers_to_gcs manual__2024-08-14T20:43:10.489736+00:00 [queued]>
[2024-08-14T20:51:28.089+0000] {taskinstance.py:1359} INFO - Starting attempt 2 of 4
[2024-08-14T20:51:28.129+0000] {taskinstance.py:1380} INFO - Executing <Task(PostgresToGCSOperator): process_olist_customers.load_olist_customers_to_gcs> on 2024-08-14 20:43:10.489736+00:00
[2024-08-14T20:51:28.140+0000] {standard_task_runner.py:57} INFO - Started process 27783 to run task
[2024-08-14T20:51:28.147+0000] {standard_task_runner.py:84} INFO - Running: ['***', 'tasks', 'run', 'postgres_to_bigquery_etl', 'process_olist_customers.load_olist_customers_to_gcs', 'manual__2024-08-14T20:43:10.489736+00:00', '--job-id', '565', '--raw', '--subdir', 'DAGS_FOLDER/extract_from_pg.py', '--cfg-path', '/tmp/tmpoeyl889x']
[2024-08-14T20:51:28.152+0000] {standard_task_runner.py:85} INFO - Job 565: Subtask process_olist_customers.load_olist_customers_to_gcs
[2024-08-14T20:51:28.236+0000] {task_command.py:415} INFO - Running <TaskInstance: postgres_to_bigquery_etl.process_olist_customers.load_olist_customers_to_gcs manual__2024-08-14T20:43:10.489736+00:00 [running]> on host d81d956e7878
[2024-08-14T20:51:28.355+0000] {warnings.py:109} WARNING - /home/***/.local/lib/python3.8/site-packages/***/utils/context.py:206: AirflowContextDeprecationWarning: Accessing 'execution_date' from the template is deprecated and will be removed in a future version. Please use 'data_interval_start' or 'logical_date' instead.
  warnings.warn(_create_deprecation_warning(key, self._deprecation_replacements[key]))

[2024-08-14T20:51:28.437+0000] {taskinstance.py:1660} INFO - Exporting env vars: AIRFLOW_CTX_DAG_OWNER='***' AIRFLOW_CTX_DAG_ID='postgres_to_bigquery_etl' AIRFLOW_CTX_TASK_ID='process_olist_customers.load_olist_customers_to_gcs' AIRFLOW_CTX_EXECUTION_DATE='2024-08-14T20:43:10.489736+00:00' AIRFLOW_CTX_TRY_NUMBER='2' AIRFLOW_CTX_DAG_RUN_ID='manual__2024-08-14T20:43:10.489736+00:00'
[2024-08-14T20:51:28.440+0000] {sql_to_gcs.py:161} INFO - Executing query
[2024-08-14T20:51:28.482+0000] {base.py:73} INFO - Using connection ID 'source_postgres_db' for task execution.
[2024-08-14T20:51:28.667+0000] {sql_to_gcs.py:180} INFO - Writing local data files
[2024-08-14T20:51:37.293+0000] {sql_to_gcs.py:186} INFO - Uploading chunk file #0 to GCS.
[2024-08-14T20:51:37.306+0000] {connection.py:232} WARNING - Connection schemes (type: google_cloud_platform) shall not contain '_' according to RFC3986.
[2024-08-14T20:51:37.311+0000] {base.py:73} INFO - Using connection ID 'google_cloud_default' for task execution.
[2024-08-14T20:52:01.441+0000] {taskinstance.py:1935} ERROR - Task failed with exception
Traceback (most recent call last):
  File "/home/airflow/.local/lib/python3.8/site-packages/urllib3/connectionpool.py", line 714, in urlopen
    httplib_response = self._make_request(
  File "/home/airflow/.local/lib/python3.8/site-packages/urllib3/connectionpool.py", line 466, in _make_request
    six.raise_from(e, None)
  File "<string>", line 3, in raise_from
  File "/home/airflow/.local/lib/python3.8/site-packages/urllib3/connectionpool.py", line 461, in _make_request
    httplib_response = conn.getresponse()
  File "/usr/local/lib/python3.8/http/client.py", line 1348, in getresponse
    response.begin()
  File "/usr/local/lib/python3.8/http/client.py", line 316, in begin
    version, status, reason = self._read_status()
  File "/usr/local/lib/python3.8/http/client.py", line 285, in _read_status
    raise RemoteDisconnected("Remote end closed connection without"
http.client.RemoteDisconnected: Remote end closed connection without response

During handling of the above exception, another exception occurred:

Traceback (most recent call last):
  File "/home/airflow/.local/lib/python3.8/site-packages/requests/adapters.py", line 486, in send
    resp = conn.urlopen(
  File "/home/airflow/.local/lib/python3.8/site-packages/urllib3/connectionpool.py", line 798, in urlopen
    retries = retries.increment(
  File "/home/airflow/.local/lib/python3.8/site-packages/urllib3/util/retry.py", line 550, in increment
    raise six.reraise(type(error), error, _stacktrace)
  File "/home/airflow/.local/lib/python3.8/site-packages/urllib3/packages/six.py", line 769, in reraise
    raise value.with_traceback(tb)
  File "/home/airflow/.local/lib/python3.8/site-packages/urllib3/connectionpool.py", line 714, in urlopen
    httplib_response = self._make_request(
  File "/home/airflow/.local/lib/python3.8/site-packages/urllib3/connectionpool.py", line 466, in _make_request
    six.raise_from(e, None)
  File "<string>", line 3, in raise_from
  File "/home/airflow/.local/lib/python3.8/site-packages/urllib3/connectionpool.py", line 461, in _make_request
    httplib_response = conn.getresponse()
  File "/usr/local/lib/python3.8/http/client.py", line 1348, in getresponse
    response.begin()
  File "/usr/local/lib/python3.8/http/client.py", line 316, in begin
    version, status, reason = self._read_status()
  File "/usr/local/lib/python3.8/http/client.py", line 285, in _read_status
    raise RemoteDisconnected("Remote end closed connection without"
urllib3.exceptions.ProtocolError: ('Connection aborted.', RemoteDisconnected('Remote end closed connection without response'))

During handling of the above exception, another exception occurred:

Traceback (most recent call last):
  File "/home/airflow/.local/lib/python3.8/site-packages/airflow/providers/google/cloud/transfers/sql_to_gcs.py", line 187, in execute
    self._upload_to_gcs(file_to_upload)
  File "/home/airflow/.local/lib/python3.8/site-packages/airflow/providers/google/cloud/transfers/sql_to_gcs.py", line 494, in _upload_to_gcs
    hook.upload(
  File "/home/airflow/.local/lib/python3.8/site-packages/airflow/providers/google/cloud/hooks/gcs.py", line 558, in upload
    _call_with_retry(
  File "/home/airflow/.local/lib/python3.8/site-packages/airflow/providers/google/cloud/hooks/gcs.py", line 513, in _call_with_retry
    f()
  File "/home/airflow/.local/lib/python3.8/site-packages/google/cloud/storage/blob.py", line 2684, in upload_from_filename
    self.upload_from_file(
  File "/home/airflow/.local/lib/python3.8/site-packages/google/cloud/storage/blob.py", line 2540, in upload_from_file
    created_json = self._do_upload(
  File "/home/airflow/.local/lib/python3.8/site-packages/google/cloud/storage/blob.py", line 2371, in _do_upload
    response = self._do_resumable_upload(
  File "/home/airflow/.local/lib/python3.8/site-packages/google/cloud/storage/blob.py", line 2198, in _do_resumable_upload
    upload, transport = self._initiate_resumable_upload(
  File "/home/airflow/.local/lib/python3.8/site-packages/google/cloud/storage/blob.py", line 2079, in _initiate_resumable_upload
    upload.initiate(
  File "/home/airflow/.local/lib/python3.8/site-packages/google/resumable_media/requests/upload.py", line 420, in initiate
    return _request_helpers.wait_and_retry(
  File "/home/airflow/.local/lib/python3.8/site-packages/google/resumable_media/requests/_request_helpers.py", line 178, in wait_and_retry
    raise error
  File "/home/airflow/.local/lib/python3.8/site-packages/google/resumable_media/requests/_request_helpers.py", line 155, in wait_and_retry
    response = func()
  File "/home/airflow/.local/lib/python3.8/site-packages/google/resumable_media/requests/upload.py", line 412, in retriable_request
    result = transport.request(
  File "/home/airflow/.local/lib/python3.8/site-packages/google/auth/transport/requests.py", line 549, in request
    response = super(AuthorizedSession, self).request(
  File "/home/airflow/.local/lib/python3.8/site-packages/requests/sessions.py", line 589, in request
    resp = self.send(prep, **send_kwargs)
  File "/home/airflow/.local/lib/python3.8/site-packages/requests/sessions.py", line 703, in send
    r = adapter.send(request, **kwargs)
  File "/home/airflow/.local/lib/python3.8/site-packages/requests/adapters.py", line 501, in send
    raise ConnectionError(err, request=request)
requests.exceptions.ConnectionError: ('Connection aborted.', RemoteDisconnected('Remote end closed connection without response'))
[2024-08-14T20:52:01.468+0000] {taskinstance.py:1398} INFO - Marking task as UP_FOR_RETRY. dag_id=postgres_to_bigquery_etl, task_id=process_olist_customers.load_olist_customers_to_gcs, execution_date=20240814T204310, start_date=20240814T205128, end_date=20240814T205201
[2024-08-14T20:52:01.513+0000] {standard_task_runner.py:104} ERROR - Failed to execute job 565 for task process_olist_customers.load_olist_customers_to_gcs (('Connection aborted.', RemoteDisconnected('Remote end closed connection without response')); 27783)
[2024-08-14T20:52:01.540+0000] {local_task_job_runner.py:228} INFO - Task exited with return code 1
[2024-08-14T20:52:01.608+0000] {taskinstance.py:2776} INFO - 0 downstream tasks scheduled from follow-on schedule check
