[2024-08-14T19:20:56.384+0000] {taskinstance.py:1157} INFO - Dependencies all met for dep_context=non-requeueable deps ti=<TaskInstance: postgres_to_bigquery_etl.create_gcs_bucket manual__2024-08-14T19:20:39.229117+00:00 [queued]>
[2024-08-14T19:20:56.435+0000] {taskinstance.py:1157} INFO - Dependencies all met for dep_context=requeueable deps ti=<TaskInstance: postgres_to_bigquery_etl.create_gcs_bucket manual__2024-08-14T19:20:39.229117+00:00 [queued]>
[2024-08-14T19:20:56.436+0000] {taskinstance.py:1359} INFO - Starting attempt 1 of 4
[2024-08-14T19:20:56.683+0000] {taskinstance.py:1380} INFO - Executing <Task(GCSCreateBucketOperator): create_gcs_bucket> on 2024-08-14 19:20:39.229117+00:00
[2024-08-14T19:20:56.734+0000] {standard_task_runner.py:57} INFO - Started process 26416 to run task
[2024-08-14T19:20:56.758+0000] {standard_task_runner.py:84} INFO - Running: ['***', 'tasks', 'run', 'postgres_to_bigquery_etl', 'create_gcs_bucket', 'manual__2024-08-14T19:20:39.229117+00:00', '--job-id', '527', '--raw', '--subdir', 'DAGS_FOLDER/extract_from_pg.py', '--cfg-path', '/tmp/tmp6e6obrl2']
[2024-08-14T19:20:56.772+0000] {standard_task_runner.py:85} INFO - Job 527: Subtask create_gcs_bucket
[2024-08-14T19:20:57.033+0000] {task_command.py:415} INFO - Running <TaskInstance: postgres_to_bigquery_etl.create_gcs_bucket manual__2024-08-14T19:20:39.229117+00:00 [running]> on host d81d956e7878
[2024-08-14T19:20:57.559+0000] {taskinstance.py:1660} INFO - Exporting env vars: AIRFLOW_CTX_DAG_OWNER='***' AIRFLOW_CTX_DAG_ID='postgres_to_bigquery_etl' AIRFLOW_CTX_TASK_ID='create_gcs_bucket' AIRFLOW_CTX_EXECUTION_DATE='2024-08-14T19:20:39.229117+00:00' AIRFLOW_CTX_TRY_NUMBER='1' AIRFLOW_CTX_DAG_RUN_ID='manual__2024-08-14T19:20:39.229117+00:00'
[2024-08-14T19:20:57.595+0000] {connection.py:232} WARNING - Connection schemes (type: google_cloud_platform) shall not contain '_' according to RFC3986.
[2024-08-14T19:20:57.668+0000] {base.py:73} INFO - Using connection ID 'google_cloud_default' for task execution.
[2024-08-14T19:20:57.721+0000] {gcs.py:1066} INFO - Creating Bucket: stg-olist-ecommerce-dataset2; Location: europe-west2; Storage Class: REGIONAL
[2024-08-14T19:21:13.884+0000] {connectionpool.py:823} WARNING - Retrying (Retry(total=2, connect=None, read=None, redirect=None, status=None)) after connection broken by 'NewConnectionError('<urllib3.connection.HTTPSConnection object at 0x70bfc613ebe0>: Failed to establish a new connection: [Errno -3] Temporary failure in name resolution')': /token
[2024-08-14T19:21:29.911+0000] {connectionpool.py:823} WARNING - Retrying (Retry(total=1, connect=None, read=None, redirect=None, status=None)) after connection broken by 'NewConnectionError('<urllib3.connection.HTTPSConnection object at 0x70bfc613ed60>: Failed to establish a new connection: [Errno -3] Temporary failure in name resolution')': /token
[2024-08-14T19:21:45.924+0000] {connectionpool.py:823} WARNING - Retrying (Retry(total=0, connect=None, read=None, redirect=None, status=None)) after connection broken by 'NewConnectionError('<urllib3.connection.HTTPSConnection object at 0x70bfc613eee0>: Failed to establish a new connection: [Errno -3] Temporary failure in name resolution')': /token
[2024-08-14T19:22:18.471+0000] {connectionpool.py:823} WARNING - Retrying (Retry(total=2, connect=None, read=None, redirect=None, status=None)) after connection broken by 'NewConnectionError('<urllib3.connection.HTTPSConnection object at 0x70bfc61626d0>: Failed to establish a new connection: [Errno -3] Temporary failure in name resolution')': /token
[2024-08-14T19:22:34.481+0000] {connectionpool.py:823} WARNING - Retrying (Retry(total=1, connect=None, read=None, redirect=None, status=None)) after connection broken by 'NewConnectionError('<urllib3.connection.HTTPSConnection object at 0x70bfc6162880>: Failed to establish a new connection: [Errno -3] Temporary failure in name resolution')': /token
[2024-08-14T19:22:50.491+0000] {connectionpool.py:823} WARNING - Retrying (Retry(total=0, connect=None, read=None, redirect=None, status=None)) after connection broken by 'NewConnectionError('<urllib3.connection.HTTPSConnection object at 0x70bfc6162a60>: Failed to establish a new connection: [Errno -3] Temporary failure in name resolution')': /token
[2024-08-14T19:22:58.766+0000] {taskinstance.py:1398} INFO - Marking task as SUCCESS. dag_id=postgres_to_bigquery_etl, task_id=create_gcs_bucket, execution_date=20240814T192039, start_date=20240814T192056, end_date=20240814T192258
[2024-08-14T19:22:58.934+0000] {local_task_job_runner.py:228} INFO - Task exited with return code 0
[2024-08-14T19:22:59.019+0000] {taskinstance.py:2776} INFO - 1 downstream tasks scheduled from follow-on schedule check
